2025-03-03 05:24:39,261 - __main__ - INFO - Coser社群Bot启动中...
2025-03-03 05:24:39,289 - __main__ - INFO - Coser社群Bot已启动
2025-03-03 05:24:40,727 - apscheduler.scheduler - INFO - Scheduler started
2025-03-03 05:30:19,921 - __main__ - INFO - Coser社群Bot启动中...
2025-03-03 05:30:19,937 - __main__ - INFO - Coser社群Bot已启动
2025-03-03 05:30:21,169 - apscheduler.scheduler - INFO - Scheduler started
2025-03-03 05:35:18,071 - __main__ - INFO - Coser社群Bot启动中...
2025-03-03 05:35:18,074 - __main__ - INFO - 数据库连接成功: coser_bot.db
2025-03-03 05:35:18,099 - __main__ - INFO - 数据库表初始化完成
2025-03-03 05:35:18,103 - __main__ - INFO - 数据库连接已关闭
2025-03-03 05:35:33,864 - __main__ - INFO - Coser社群Bot启动中...
2025-03-03 05:35:33,868 - __main__ - INFO - 数据库连接成功: coser_bot.db
2025-03-03 05:35:33,871 - __main__ - INFO - 数据库表初始化完成
2025-03-03 05:35:33,871 - __main__ - INFO - 数据库连接已关闭
2025-03-03 05:37:06,643 - __main__ - INFO - Coser社群Bot启动中...
2025-03-03 05:37:06,645 - __main__ - INFO - 数据库连接成功: coser_bot.db
2025-03-03 05:37:06,647 - __main__ - INFO - 数据库表初始化完成
2025-03-03 05:37:06,647 - __main__ - INFO - 数据库连接已关闭
2025-03-03 05:37:06,661 - __main__ - INFO - Coser社群Bot已启动
2025-03-03 05:37:38,766 - telegram.ext.Updater - ERROR - Error while getting Updates: Conflict: terminated by other getUpdates request; make sure that only one bot instance is running
2025-03-03 05:37:38,767 - telegram.ext.Application - ERROR - No error handlers are registered, logging exception.
Traceback (most recent call last):
  File "C:\Python39\lib\site-packages\telegram\ext\_updater.py", line 688, in _network_loop_retry
    if not await action_cb():
  File "C:\Python39\lib\site-packages\telegram\ext\_updater.py", line 384, in polling_action_cb
    raise exc
  File "C:\Python39\lib\site-packages\telegram\ext\_updater.py", line 373, in polling_action_cb
    updates = await self.bot.get_updates(
  File "C:\Python39\lib\site-packages\telegram\ext\_extbot.py", line 558, in get_updates
    updates = await super().get_updates(
  File "C:\Python39\lib\site-packages\telegram\_bot.py", line 525, in decorator
    result = await func(self, *args, **kwargs)  # skipcq: PYL-E1102
  File "C:\Python39\lib\site-packages\telegram\_bot.py", line 3584, in get_updates
    await self._post(
  File "C:\Python39\lib\site-packages\telegram\_bot.py", line 613, in _post
    return await self._do_post(
  File "C:\Python39\lib\site-packages\telegram\ext\_extbot.py", line 340, in _do_post
    return await super()._do_post(
  File "C:\Python39\lib\site-packages\telegram\_bot.py", line 641, in _do_post
    return await request.post(
  File "C:\Python39\lib\site-packages\telegram\request\_baserequest.py", line 200, in post
    result = await self._request_wrapper(
  File "C:\Python39\lib\site-packages\telegram\request\_baserequest.py", line 381, in _request_wrapper
    raise Conflict(message)
telegram.error.Conflict: Conflict: terminated by other getUpdates request; make sure that only one bot instance is running
2025-03-03 05:37:44,383 - telegram.ext.Updater - ERROR - Error while getting Updates: Conflict: terminated by other getUpdates request; make sure that only one bot instance is running
2025-03-03 05:37:44,383 - telegram.ext.Application - ERROR - No error handlers are registered, logging exception.
Traceback (most recent call last):
  File "C:\Python39\lib\site-packages\telegram\ext\_updater.py", line 688, in _network_loop_retry
    if not await action_cb():
  File "C:\Python39\lib\site-packages\telegram\ext\_updater.py", line 384, in polling_action_cb
    raise exc
  File "C:\Python39\lib\site-packages\telegram\ext\_updater.py", line 373, in polling_action_cb
    updates = await self.bot.get_updates(
  File "C:\Python39\lib\site-packages\telegram\ext\_extbot.py", line 558, in get_updates
    updates = await super().get_updates(
  File "C:\Python39\lib\site-packages\telegram\_bot.py", line 525, in decorator
    result = await func(self, *args, **kwargs)  # skipcq: PYL-E1102
  File "C:\Python39\lib\site-packages\telegram\_bot.py", line 3584, in get_updates
    await self._post(
  File "C:\Python39\lib\site-packages\telegram\_bot.py", line 613, in _post
    return await self._do_post(
  File "C:\Python39\lib\site-packages\telegram\ext\_extbot.py", line 340, in _do_post
    return await super()._do_post(
  File "C:\Python39\lib\site-packages\telegram\_bot.py", line 641, in _do_post
    return await request.post(
  File "C:\Python39\lib\site-packages\telegram\request\_baserequest.py", line 200, in post
    result = await self._request_wrapper(
  File "C:\Python39\lib\site-packages\telegram\request\_baserequest.py", line 381, in _request_wrapper
    raise Conflict(message)
telegram.error.Conflict: Conflict: terminated by other getUpdates request; make sure that only one bot instance is running
2025-03-03 05:37:51,040 - telegram.ext.Updater - ERROR - Error while getting Updates: Conflict: terminated by other getUpdates request; make sure that only one bot instance is running
2025-03-03 05:37:51,040 - telegram.ext.Application - ERROR - No error handlers are registered, logging exception.
Traceback (most recent call last):
  File "C:\Python39\lib\site-packages\telegram\ext\_updater.py", line 688, in _network_loop_retry
    if not await action_cb():
  File "C:\Python39\lib\site-packages\telegram\ext\_updater.py", line 384, in polling_action_cb
    raise exc
  File "C:\Python39\lib\site-packages\telegram\ext\_updater.py", line 373, in polling_action_cb
    updates = await self.bot.get_updates(
  File "C:\Python39\lib\site-packages\telegram\ext\_extbot.py", line 558, in get_updates
    updates = await super().get_updates(
  File "C:\Python39\lib\site-packages\telegram\_bot.py", line 525, in decorator
    result = await func(self, *args, **kwargs)  # skipcq: PYL-E1102
  File "C:\Python39\lib\site-packages\telegram\_bot.py", line 3584, in get_updates
    await self._post(
  File "C:\Python39\lib\site-packages\telegram\_bot.py", line 613, in _post
    return await self._do_post(
  File "C:\Python39\lib\site-packages\telegram\ext\_extbot.py", line 340, in _do_post
    return await super()._do_post(
  File "C:\Python39\lib\site-packages\telegram\_bot.py", line 641, in _do_post
    return await request.post(
  File "C:\Python39\lib\site-packages\telegram\request\_baserequest.py", line 200, in post
    result = await self._request_wrapper(
  File "C:\Python39\lib\site-packages\telegram\request\_baserequest.py", line 381, in _request_wrapper
    raise Conflict(message)
telegram.error.Conflict: Conflict: terminated by other getUpdates request; make sure that only one bot instance is running
2025-03-03 05:37:57,910 - telegram.ext.Updater - ERROR - Error while getting Updates: Conflict: terminated by other getUpdates request; make sure that only one bot instance is running
2025-03-03 05:37:57,910 - telegram.ext.Application - ERROR - No error handlers are registered, logging exception.
Traceback (most recent call last):
  File "C:\Python39\lib\site-packages\telegram\ext\_updater.py", line 688, in _network_loop_retry
    if not await action_cb():
  File "C:\Python39\lib\site-packages\telegram\ext\_updater.py", line 384, in polling_action_cb
    raise exc
  File "C:\Python39\lib\site-packages\telegram\ext\_updater.py", line 373, in polling_action_cb
    updates = await self.bot.get_updates(
  File "C:\Python39\lib\site-packages\telegram\ext\_extbot.py", line 558, in get_updates
    updates = await super().get_updates(
  File "C:\Python39\lib\site-packages\telegram\_bot.py", line 525, in decorator
    result = await func(self, *args, **kwargs)  # skipcq: PYL-E1102
  File "C:\Python39\lib\site-packages\telegram\_bot.py", line 3584, in get_updates
    await self._post(
  File "C:\Python39\lib\site-packages\telegram\_bot.py", line 613, in _post
    return await self._do_post(
  File "C:\Python39\lib\site-packages\telegram\ext\_extbot.py", line 340, in _do_post
    return await super()._do_post(
  File "C:\Python39\lib\site-packages\telegram\_bot.py", line 641, in _do_post
    return await request.post(
  File "C:\Python39\lib\site-packages\telegram\request\_baserequest.py", line 200, in post
    result = await self._request_wrapper(
  File "C:\Python39\lib\site-packages\telegram\request\_baserequest.py", line 381, in _request_wrapper
    raise Conflict(message)
telegram.error.Conflict: Conflict: terminated by other getUpdates request; make sure that only one bot instance is running
2025-03-03 05:38:03,533 - telegram.ext.Updater - ERROR - Error while getting Updates: Conflict: terminated by other getUpdates request; make sure that only one bot instance is running
2025-03-03 05:38:03,534 - telegram.ext.Application - ERROR - No error handlers are registered, logging exception.
Traceback (most recent call last):
  File "C:\Python39\lib\site-packages\telegram\ext\_updater.py", line 688, in _network_loop_retry
    if not await action_cb():
  File "C:\Python39\lib\site-packages\telegram\ext\_updater.py", line 384, in polling_action_cb
    raise exc
  File "C:\Python39\lib\site-packages\telegram\ext\_updater.py", line 373, in polling_action_cb
    updates = await self.bot.get_updates(
  File "C:\Python39\lib\site-packages\telegram\ext\_extbot.py", line 558, in get_updates
    updates = await super().get_updates(
  File "C:\Python39\lib\site-packages\telegram\_bot.py", line 525, in decorator
    result = await func(self, *args, **kwargs)  # skipcq: PYL-E1102
  File "C:\Python39\lib\site-packages\telegram\_bot.py", line 3584, in get_updates
    await self._post(
  File "C:\Python39\lib\site-packages\telegram\_bot.py", line 613, in _post
    return await self._do_post(
  File "C:\Python39\lib\site-packages\telegram\ext\_extbot.py", line 340, in _do_post
    return await super()._do_post(
  File "C:\Python39\lib\site-packages\telegram\_bot.py", line 641, in _do_post
    return await request.post(
  File "C:\Python39\lib\site-packages\telegram\request\_baserequest.py", line 200, in post
    result = await self._request_wrapper(
  File "C:\Python39\lib\site-packages\telegram\request\_baserequest.py", line 381, in _request_wrapper
    raise Conflict(message)
telegram.error.Conflict: Conflict: terminated by other getUpdates request; make sure that only one bot instance is running
2025-03-03 05:38:09,147 - telegram.ext.Updater - ERROR - Error while getting Updates: Conflict: terminated by other getUpdates request; make sure that only one bot instance is running
2025-03-03 05:38:09,148 - telegram.ext.Application - ERROR - No error handlers are registered, logging exception.
Traceback (most recent call last):
  File "C:\Python39\lib\site-packages\telegram\ext\_updater.py", line 688, in _network_loop_retry
    if not await action_cb():
  File "C:\Python39\lib\site-packages\telegram\ext\_updater.py", line 384, in polling_action_cb
    raise exc
  File "C:\Python39\lib\site-packages\telegram\ext\_updater.py", line 373, in polling_action_cb
    updates = await self.bot.get_updates(
  File "C:\Python39\lib\site-packages\telegram\ext\_extbot.py", line 558, in get_updates
    updates = await super().get_updates(
  File "C:\Python39\lib\site-packages\telegram\_bot.py", line 525, in decorator
    result = await func(self, *args, **kwargs)  # skipcq: PYL-E1102
  File "C:\Python39\lib\site-packages\telegram\_bot.py", line 3584, in get_updates
    await self._post(
  File "C:\Python39\lib\site-packages\telegram\_bot.py", line 613, in _post
    return await self._do_post(
  File "C:\Python39\lib\site-packages\telegram\ext\_extbot.py", line 340, in _do_post
    return await super()._do_post(
  File "C:\Python39\lib\site-packages\telegram\_bot.py", line 641, in _do_post
    return await request.post(
  File "C:\Python39\lib\site-packages\telegram\request\_baserequest.py", line 200, in post
    result = await self._request_wrapper(
  File "C:\Python39\lib\site-packages\telegram\request\_baserequest.py", line 381, in _request_wrapper
    raise Conflict(message)
telegram.error.Conflict: Conflict: terminated by other getUpdates request; make sure that only one bot instance is running
2025-03-03 05:38:15,258 - telegram.ext.Updater - ERROR - Error while getting Updates: Conflict: terminated by other getUpdates request; make sure that only one bot instance is running
2025-03-03 05:38:15,258 - telegram.ext.Application - ERROR - No error handlers are registered, logging exception.
Traceback (most recent call last):
  File "C:\Python39\lib\site-packages\telegram\ext\_updater.py", line 688, in _network_loop_retry
    if not await action_cb():
  File "C:\Python39\lib\site-packages\telegram\ext\_updater.py", line 384, in polling_action_cb
    raise exc
  File "C:\Python39\lib\site-packages\telegram\ext\_updater.py", line 373, in polling_action_cb
    updates = await self.bot.get_updates(
  File "C:\Python39\lib\site-packages\telegram\ext\_extbot.py", line 558, in get_updates
    updates = await super().get_updates(
  File "C:\Python39\lib\site-packages\telegram\_bot.py", line 525, in decorator
    result = await func(self, *args, **kwargs)  # skipcq: PYL-E1102
  File "C:\Python39\lib\site-packages\telegram\_bot.py", line 3584, in get_updates
    await self._post(
  File "C:\Python39\lib\site-packages\telegram\_bot.py", line 613, in _post
    return await self._do_post(
  File "C:\Python39\lib\site-packages\telegram\ext\_extbot.py", line 340, in _do_post
    return await super()._do_post(
  File "C:\Python39\lib\site-packages\telegram\_bot.py", line 641, in _do_post
    return await request.post(
  File "C:\Python39\lib\site-packages\telegram\request\_baserequest.py", line 200, in post
    result = await self._request_wrapper(
  File "C:\Python39\lib\site-packages\telegram\request\_baserequest.py", line 381, in _request_wrapper
    raise Conflict(message)
telegram.error.Conflict: Conflict: terminated by other getUpdates request; make sure that only one bot instance is running
2025-03-03 05:38:22,110 - telegram.ext.Updater - ERROR - Error while getting Updates: Conflict: terminated by other getUpdates request; make sure that only one bot instance is running
2025-03-03 05:38:22,111 - telegram.ext.Application - ERROR - No error handlers are registered, logging exception.
Traceback (most recent call last):
  File "C:\Python39\lib\site-packages\telegram\ext\_updater.py", line 688, in _network_loop_retry
    if not await action_cb():
  File "C:\Python39\lib\site-packages\telegram\ext\_updater.py", line 384, in polling_action_cb
    raise exc
  File "C:\Python39\lib\site-packages\telegram\ext\_updater.py", line 373, in polling_action_cb
    updates = await self.bot.get_updates(
  File "C:\Python39\lib\site-packages\telegram\ext\_extbot.py", line 558, in get_updates
    updates = await super().get_updates(
  File "C:\Python39\lib\site-packages\telegram\_bot.py", line 525, in decorator
    result = await func(self, *args, **kwargs)  # skipcq: PYL-E1102
  File "C:\Python39\lib\site-packages\telegram\_bot.py", line 3584, in get_updates
    await self._post(
  File "C:\Python39\lib\site-packages\telegram\_bot.py", line 613, in _post
    return await self._do_post(
  File "C:\Python39\lib\site-packages\telegram\ext\_extbot.py", line 340, in _do_post
    return await super()._do_post(
  File "C:\Python39\lib\site-packages\telegram\_bot.py", line 641, in _do_post
    return await request.post(
  File "C:\Python39\lib\site-packages\telegram\request\_baserequest.py", line 200, in post
    result = await self._request_wrapper(
  File "C:\Python39\lib\site-packages\telegram\request\_baserequest.py", line 381, in _request_wrapper
    raise Conflict(message)
telegram.error.Conflict: Conflict: terminated by other getUpdates request; make sure that only one bot instance is running
2025-03-03 05:38:30,590 - telegram.ext.Updater - ERROR - Error while getting Updates: Conflict: terminated by other getUpdates request; make sure that only one bot instance is running
2025-03-03 05:38:30,590 - telegram.ext.Application - ERROR - No error handlers are registered, logging exception.
Traceback (most recent call last):
  File "C:\Python39\lib\site-packages\telegram\ext\_updater.py", line 688, in _network_loop_retry
    if not await action_cb():
  File "C:\Python39\lib\site-packages\telegram\ext\_updater.py", line 384, in polling_action_cb
    raise exc
  File "C:\Python39\lib\site-packages\telegram\ext\_updater.py", line 373, in polling_action_cb
    updates = await self.bot.get_updates(
  File "C:\Python39\lib\site-packages\telegram\ext\_extbot.py", line 558, in get_updates
    updates = await super().get_updates(
  File "C:\Python39\lib\site-packages\telegram\_bot.py", line 525, in decorator
    result = await func(self, *args, **kwargs)  # skipcq: PYL-E1102
  File "C:\Python39\lib\site-packages\telegram\_bot.py", line 3584, in get_updates
    await self._post(
  File "C:\Python39\lib\site-packages\telegram\_bot.py", line 613, in _post
    return await self._do_post(
  File "C:\Python39\lib\site-packages\telegram\ext\_extbot.py", line 340, in _do_post
    return await super()._do_post(
  File "C:\Python39\lib\site-packages\telegram\_bot.py", line 641, in _do_post
    return await request.post(
  File "C:\Python39\lib\site-packages\telegram\request\_baserequest.py", line 200, in post
    result = await self._request_wrapper(
  File "C:\Python39\lib\site-packages\telegram\request\_baserequest.py", line 381, in _request_wrapper
    raise Conflict(message)
telegram.error.Conflict: Conflict: terminated by other getUpdates request; make sure that only one bot instance is running
